Workbook

Sheet 经营目标
B2: 2026年度经营指标及目标
B3: 序号 | C3: 企业名称 | D3: 指标类别 | E3: 类型 | F3: 指标名称 | G3: 板块/公司/产品 | H3: 重点任务/项目名称 | I3: 计量 单位 | J3: 2023年 实际数 | K3: 2024年 实际数 | L3: 2025年 预计数 | M3: 2026年 拟定目标值 | N3: 差值 （26年-25年） | O3: 备注 （目标值同比变动幅度±10%，请说明原因）
B4: 1 | C4: 北京海创元人工智能教育科技有限公司 | D4: 业绩类指标 | E4: 考核 | F4: 营业收入 | G4: 海创元 | I4: 万元 | L4: 61 | M4: ='附件2 经营性净现金流利润编制明细2026415'!E5 -> 2884.035 | N4: =M4-L4 -> 2823.035 | O4: 2025年考核标准为合同签约额，2026年考核标准为财务收入，在此说明
B5: 2 | C5: 北京海创元人工智能教育科技有限公司 | D5: 业绩类指标 | E5: 考核 | F5: 利润总额 | G5: 海创元 | I5: 万元 | L5: -343 | M5: ='附件2 经营性净现金流利润编制明细2026415'!E38 -> 1.0398117 | N5: =M5-L5 -> 344.03981
B6: 3 | C6: 北京海创元人工智能教育科技有限公司 | D6: 业绩类指标 | E6: 考核 | F6: 销管研费用 | G6: 海创元 | I6: 万元 | L6: 345 | M6: ='附件2 经营性净现金流利润编制明细2026415'!E24+'附件2 经营性净现金流利润编制明细2026415'!E27+'附件2 经营性净现金流利润编制明细2026415'!E30 -> 1163.7141 | N6: =M6-L6 -> 818.71406
B7: 4 | C7: 北京海创元人工智能教育科技有限公司 | D7: 业绩类指标 | E7: 关注 | F7: 成本费用总额 | G7: 海创元 | I7: 万元 | L7: ='[1]预算分板块对比分析-国投其他'!$D$31+'[1]预算分板块对比分析-国投其他'!$D$39+'[1]预算分板块对比分析-国投其他'!$D$40 -> 404.24 | M7: ='附件2 经营性净现金流利润编制明细2026415'!E14 -> 2882.9952 | N7: =M7-L7 -> 2478.7552
B8: 5 | C8: 北京海创元人工智能教育科技有限公司 | D8: 业绩类指标 | E8: 关注 | F8: 经营活动产生的现金流量净额 | G8: 海创元 | I8: 万元 | L8: -277 | M8: ='附件3 经营性资金计划 2026415'!E22 -> 14.171394 | N8: =M8-L8 -> 291.17139
B9: 6 | C9: 北京海创元人工智能教育科技有限公司 | D9: 业绩类指标 | E9: 关注 | F9: 销售回款 | G9: 海创元 | I9: 万元 | L9: ='[1]预算分板块对比分析-国投其他'!$D$59 -> 101 | M9: ='附件3 经营性资金计划 2026415'!E6 -> 3001.4013 | N9: =M9-L9 -> 2900.4013
B10: 7 | C10: 北京海创元人工智能教育科技有限公司 | D10: 业绩类指标 | E10: 关注 | F10: 经营性净现金流利润 （净利润+非付现） | G10: 海创元 | I10: 万元 | L10: =L5+3 -> -340 | M10: ='附件2 经营性净现金流利润编制明细2026415'!E47 -> 14.289812 | N10: =M10-L10 -> 354.28981
B11: 8 | C11: 北京海创元人工智能教育科技有限公司 | D11: 任务类指标 | E11: 考核 | F11: 签约渠道 | G11: 海创元 | I11: 家 | L11: 43 | M11: 40 | N11: =M11-L11 -> -3
B12: 9 | C12: 北京海创元人工智能教育科技有限公司 | D12: 任务类指标 | E12: 考核 | F12: OPC接单金额 | G12: 海创元 | I12: 万元 | L12: 0 | M12: ='附件2 经营性净现金流利润编制明细2026415'!AG4 -> 425 | N12: =M12-L12 -> 425
B13: 10 | C13: 北京海创元人工智能教育科技有限公司 | D13: 任务类指标 | E13: 关注 | F13: 年度实现毛利 | G13: 海创元 | I13: 万元 | L13: =L4-'[1]预算分板块对比分析-国投其他'!$D$31 -> 3.53 | M13: ='附件2 经营性净现金流利润编制明细2026415'!E5-'附件2 经营性净现金流利润编制明细2026415'!E15 -> 1197.9952 | N13: =M13-L13 -> 1194.4652
B14: 11 | C14: 北京海创元人工智能教育科技有限公司 | D14: 任务类指标 | E14: 关注 | F14: OPC 生态打造与影响力建设 | I14: / | J14: / | K14: / | L14: / | M14: 详见指标分解 | N14: /
B15: 12 | C15: 北京海创元人工智能教育科技有限公司 | D15: 任务类指标 | E15: 关注 | F15: 生态联盟年度新增签约 | I15: 家 | L15: 4 | M15: 4 | N15: =M15-L15 -> 0
B17: 附注：
B18: 1、年度经营业绩考核指标从以上经营指标中选取，分为业绩类指标、任务类指标及管理类指标，其中： （1）业绩类指标包括收入、利润、现金流等，涉及财务类经营数据以财务报表为基础 （2）任务类指标包括与企业主业发展关联度高的核心运营指标、围绕主责主业承担的服务区域经济社会发展的重点工作和专项任务指标、年内重点管理提升工作等
B19: 2、关于任务类指标，举例如下，具体由企业根据自身情况拟定，并在备注中说明指标核算逻辑及公式：
B20: （1）市场营销方面：如销量、价格、去化面积/去化率、租赁面积、房屋出租率、贸易量、业务额、年度回款额、客流量（车）、运营车辆数、在校生数量等。
B21: （2）生产管理方面：如原料加工量、产量、产能利用率（装置负荷率或设备有效运行时间等）、产品加工成本/生产成本等。
B22: （3）资产运营方面：如固定资产投资完成率、存货周转率、应收账款周转率等。
B23: （4）项目管理方面：如重点项目里程碑以及进度、成本等方面控制指标。
B24: （5）其他业务方面：除以上指标外的其他业务指标，如人均效能等。
B25: 3、若经营目标值较去年同期相比变动幅度±10%，请在备注中解释说明原因。
B26: 4、若企业涉及多板块业务，在指标分类基础上，请按板块、公司等分类列示；若不涉及则直接填写“/”。
B27: 5、以上内容涉及的企业发展规划、项目资料、历史数据、测算明细表等与经营计划一并提供，并根据集团经营部需要补充。

Sheet 附件1 指标分解
B2: 2026年经营指标分解
B3: 序号 | C3: 指标类别 | D3: 类型 | E3: 指标名称 | F3: 计量 单位 | G3: 年度目标 | H3: 年度目标分解
H4: 1月 | I4: 2月 | J4: 3月 | K4: 4月 | L4: 5月 | M4: 6月 | N4: 7月 | O4: 8月 | P4: 9月 | Q4: 10月 | R4: 11月 | S4: 12月 | T4: 校验
B5: 1 | C5: =经营目标!D4 -> 业绩类指标 | D5: =经营目标!E4 -> 考核 | E5: 营业收入 | F5: =经营目标!I4 -> 万元 | G5: =经营目标!M4 -> 2884.035 | H5: ='附件2 经营性净现金流利润编制明细2026415'!F5 -> 18.046026 | I5: ='附件2 经营性净现金流利润编制明细2026415'!G5 -> 18.046026 | J5: ='附件2 经营性净现金流利润编制明细2026415'!H5 -> 270.69039 | K5: ='附件2 经营性净现金流利润编制明细2026415'!I5 -> 354.14078 | L5: ='附件2 经营性净现金流利润编制明细2026415'!J5 -> 354.14078 | M5: ='附件2 经营性净现金流利润编制明细2026415'!K5 -> 354.14078 | N5: ='附件2 经营性净现金流利润编制明细2026415'!L5 -> 226.13836 | O5: ='附件2 经营性净现金流利润编制明细2026415'!M5 -> 256.13836 | ... S5: ='附件2 经营性净现金流利润编制明细2026415'!Q5 -> 258.80503 | T5: =G5-SUM(H5:S5) -> -4.0927262e-12
B6: 2 | C6: =经营目标!D5 -> 业绩类指标 | D6: =经营目标!E5 -> 考核 | E6: =经营目标!F5 -> 利润总额 | F6: =经营目标!I5 -> 万元 | G6: =经营目标!M5 -> 1.0398117 | H6: ='附件2 经营性净现金流利润编制明细2026415'!F38 -> -69.61925 | I6: ='附件2 经营性净现金流利润编制明细2026415'!G38 -> -66.686698 | J6: ='附件2 经营性净现金流利润编制明细2026415'!H38 -> 39.863959 | K6: ='附件2 经营性净现金流利润编制明细2026415'!I38 -> 56.793738 | L6: ='附件2 经营性净现金流利润编制明细2026415'!J38 -> 25.345322 | M6: ='附件2 经营性净现金流利润编制明细2026415'!K38 -> 27.272933 | N6: ='附件2 经营性净现金流利润编制明细2026415'!L38 -> -51.410547 | O6: ='附件2 经营性净现金流利润编制明细2026415'!M38 -> 30.318993 | ... S6: ='附件2 经营性净现金流利润编制明细2026415'!Q38 -> -74.745238 | T6: =G6-SUM(H6:S6) -> -2.220446e-15
B7: 3 | C7: =经营目标!D6 -> 业绩类指标 | D7: =经营目标!E6 -> 考核 | E7: =经营目标!F6 -> 销管研费用 | F7: =经营目标!I6 -> 万元 | G7: =经营目标!M6 -> 1163.7141 | H7: ='附件2 经营性净现金流利润编制明细2026415'!F24+'附件2 经营性净现金流利润编制明细2026415'!F27+'附件2 经营性净现金流利润编制明细2026415'!F30 -> 78.642201 | I7: ='附件2 经营性净现金流利润编制明细2026415'!G24+'附件2 经营性净现金流利润编制明细2026415'!G27+'附件2 经营性净现金流利润编制明细2026415'!G30 -> 73.33695 | J7: ='附件2 经营性净现金流利润编制明细2026415'!H24+'附件2 经营性净现金流利润编制明细2026415'!H27+'附件2 经营性净现金流利润编制明细2026415'!H30 -> 79.962212 | K7: ='附件2 经营性净现金流利润编制明细2026415'!I24+'附件2 经营性净现金流利润编制明细2026415'!I27+'附件2 经营性净现金流利润编制明细2026415'!I30 -> 83.52848 | L7: ='附件2 经营性净现金流利润编制明细2026415'!J24+'附件2 经营性净现金流利润编制明细2026415'!J27+'附件2 经营性净现金流利润编制明细2026415'!J30 -> 83.811678 | M7: ='附件2 经营性净现金流利润编制明细2026415'!K24+'附件2 经营性净现金流利润编制明细2026415'!K27+'附件2 经营性净现金流利润编制明细2026415'!K30 -> 82.012013 | N7: ='附件2 经营性净现金流利润编制明细2026415'!L24+'附件2 经营性净现金流利润编制明细2026415'!L27+'附件2 经营性净现金流利润编制明细2026415'!L30 -> 135.41714 | O7: ='附件2 经营性净现金流利润编制明细2026415'!M24+'附件2 经营性净现金流利润编制明细2026415'!M27+'附件2 经营性净现金流利润编制明细2026415'!M30 -> 83.840592 | ... S7: ='附件2 经营性净现金流利润编制明细2026415'!Q24+'附件2 经营性净现金流利润编制明细2026415'!Q27+'附件2 经营性净现金流利润编制明细2026415'!Q30 -> 194.18245 | T7: =G7-SUM(H7:S7) -> 0
B8: 4 | C8: =经营目标!D7 -> 业绩类指标 | D8: =经营目标!E7 -> 关注 | E8: =经营目标!F7 -> 成本费用总额 | F8: =经营目标!I7 -> 万元 | G8: =经营目标!M7 -> 2882.9952 | H8: ='附件2 经营性净现金流利润编制明细2026415'!F14 -> 87.665276 | I8: ='附件2 经营性净现金流利润编制明细2026415'!G14 -> 84.732725 | J8: ='附件2 经营性净现金流利润编制明细2026415'!H14 -> 230.82644 | K8: ='附件2 经营性净现金流利润编制明细2026415'!I14 -> 297.34704 | L8: ='附件2 经营性净现金流利润编制明细2026415'!J14 -> 328.79546 | M8: ='附件2 经营性净现金流利润编制明细2026415'!K14 -> 326.86784 | N8: ='附件2 经营性净现金流利润编制明细2026415'!L14 -> 277.54891 | O8: ='附件2 经营性净现金流利润编制明细2026415'!M14 -> 225.81937 | ... S8: ='附件2 经营性净现金流利润编制明细2026415'!Q14 -> 333.55027 | T8: =G8-SUM(H8:S8) -> 0
B9: 5 | C9: =经营目标!D8 -> 业绩类指标 | D9: =经营目标!E8 -> 关注 | E9: =经营目标!F8 -> 经营活动产生的现金流量净额 | F9: =经营目标!I8 -> 万元 | G9: =经营目标!M8 -> 14.171394 | H9: ='附件3 经营性资金计划 2026415'!F22 -> -78.58 | I9: ='附件3 经营性资金计划 2026415'!G22 -> -86.1 | J9: ='附件3 经营性资金计划 2026415'!H22 -> -83.353513 | K9: ='附件3 经营性资金计划 2026415'!I22 -> -119.74229 | L9: ='附件3 经营性资金计划 2026415'!J22 -> -64.677319 | M9: ='附件3 经营性资金计划 2026415'!K22 -> -9.0839698 | N9: ='附件3 经营性资金计划 2026415'!L22 -> 45.67643 | O9: ='附件3 经营性资金计划 2026415'!M22 -> 143.72932 | ... S9: ='附件3 经营性资金计划 2026415'!Q22 -> 97.259743 | T9: =G9-SUM(H9:S9) -> -2.7746694e-12
B10: 6 | C10: =经营目标!D9 -> 业绩类指标 | D10: =经营目标!E9 -> 关注 | E10: 销售回款 | F10: =经营目标!I9 -> 万元 | G10: =经营目标!M9 -> 3001.4013 | H10: ='附件3 经营性资金计划 2026415'!F6 -> 0 | I10: ='附件3 经营性资金计划 2026415'!G6 -> 0 | J10: ='附件3 经营性资金计划 2026415'!H6 -> 18.226487 | K10: ='附件3 经营性资金计划 2026415'!I6 -> 101.23585 | L10: ='附件3 经营性资金计划 2026415'!J6 -> 235.9345 | M10: ='附件3 经营性资金计划 2026415'!K6 -> 352.78302 | N10: ='附件3 经营性资金计划 2026415'!L6 -> 439.70667 | O10: ='附件3 经营性资金计划 2026415'!M6 -> 501.50667 | ... S10: ='附件3 经营性资金计划 2026415'!Q6 -> 395.13613 | T10: =G10-SUM(H10:S10) -> -3.6379788e-12
B11: 7 | C11: =经营目标!D10 -> 业绩类指标 | D11: =经营目标!E10 -> 关注 | E11: 经营性净现金流利润 （净利润+非付现） | F11: =经营目标!I10 -> 万元 | G11: =经营目标!M10 -> 14.289812 | H11: ='附件2 经营性净现金流利润编制明细2026415'!F40+'附件2 经营性净现金流利润编制明细2026415'!F41 -> -68.51925 | I11: ='附件2 经营性净现金流利润编制明细2026415'!G40+'附件2 经营性净现金流利润编制明细2026415'!G41 -> -65.586698 | J11: ='附件2 经营性净现金流利润编制明细2026415'!H40+'附件2 经营性净现金流利润编制明细2026415'!H41 -> 40.963959 | K11: ='附件2 经营性净现金流利润编制明细2026415'!I40+'附件2 经营性净现金流利润编制明细2026415'!I41 -> 57.893738 | L11: ='附件2 经营性净现金流利润编制明细2026415'!J40+'附件2 经营性净现金流利润编制明细2026415'!J41 -> 26.445322 | M11: ='附件2 经营性净现金流利润编制明细2026415'!K40+'附件2 经营性净现金流利润编制明细2026415'!K41 -> 28.372933 | N11: ='附件2 经营性净现金流利润编制明细2026415'!L40+'附件2 经营性净现金流利润编制明细2026415'!L41 -> -50.310547 | O11: ='附件2 经营性净现金流利润编制明细2026415'!M40+'附件2 经营性净现金流利润编制明细2026415'!M41 -> 31.418993 | ... S11: ='附件2 经营性净现金流利润编制明细2026415'!Q40+'附件2 经营性净现金流利润编制明细2026415'!Q41 -> -73.595238
B12: 8 | C12: =经营目标!D11 -> 任务类指标 | D12: =经营目标!E11 -> 考核 | E12: 签约渠道 | F12: =经营目标!I11 -> 家 | G12: =经营目标!M11 -> 40 | H12: 3 | I12: 2 | J12: 5 | K12: 5 | L12: 3 | M12: 5 | N12: 5 | O12: 5 | P12: 2 | Q12: 1 | R12: 2 | S12: 2 | T12: =G12-SUM(H12:S12) -> 0
B13: 9 | C13: =经营目标!D12 -> 任务类指标 | D13: =经营目标!E12 -> 考核 | E13: OPC累计接单金额 | F13: =经营目标!I12 -> 万元 | G13: =经营目标!M12 -> 425 | H13: ='附件2 经营性净现金流利润编制明细2026415'!U4 -> 0 | I13: ='附件2 经营性净现金流利润编制明细2026415'!V4 -> 0 | J13: ='附件2 经营性净现金流利润编制明细2026415'!W4 -> 0 | K13: ='附件2 经营性净现金流利润编制明细2026415'!X4 -> 0 | L13: ='附件2 经营性净现金流利润编制明细2026415'!Y4 -> 0 | M13: ='附件2 经营性净现金流利润编制明细2026415'!Z4 -> 0 | N13: ='附件2 经营性净现金流利润编制明细2026415'!AA4 -> 70.833333 | O13: ='附件2 经营性净现金流利润编制明细2026415'!AB4 -> 70.833333 | ... S13: ='附件2 经营性净现金流利润编制明细2026415'!AF4 -> 70.833333 | T13: =G13-SUM(H13:S13) -> 0
B14: 10 | C14: =经营目标!D13 -> 任务类指标 | D14: =经营目标!E13 -> 关注 | E14: =经营目标!F13 -> 年度实现毛利 | F14: =经营目标!I13 -> 万元 | G14: =经营目标!M13 -> 1197.9952 | H14: ='附件2 经营性净现金流利润编制明细2026415'!F5-'附件2 经营性净现金流利润编制明细2026415'!F15 -> 10.219452 | I14: ='附件2 经营性净现金流利润编制明细2026415'!G5-'附件2 经营性净现金流利润编制明细2026415'!G15 -> 7.9402516 | J14: ='附件2 经营性净现金流利润编制明细2026415'!H5-'附件2 经营性净现金流利润编制明细2026415'!H15 -> 121.3216 | K14: ='附件2 经营性净现金流利润编制明细2026415'!I5-'附件2 经营性净现金流利润编制明细2026415'!I15 -> 142.78137 | L14: ='附件2 经营性净现金流利润编制明细2026415'!J5-'附件2 经营性净现金流利润编制明细2026415'!J15 -> 112.78137 | M14: ='附件2 经营性净现金流利润编制明细2026415'!K5-'附件2 经营性净现金流利润编制明细2026415'!K15 -> 112.78137 | N14: ='附件2 经营性净现金流利润编制明细2026415'!L5-'附件2 经营性净现金流利润编制明细2026415'!L15 -> 87.283019 | O14: ='附件2 经营性净现金流利润编制明细2026415'!M5-'附件2 经营性净现金流利润编制明细2026415'!M15 -> 117.28302 | ... S14: ='附件2 经营性净现金流利润编制明细2026415'!Q5-'附件2 经营性净现金流利润编制明细2026415'!Q15 -> 122.77358 | T14: =G14-SUM(H14:S14) -> -5.0022209e-12
B15: 11 | C15: =经营目标!D14 -> 任务类指标 | D15: =经营目标!E14 -> 关注 | E15: =经营目标!F14 -> OPC 生态打造与影响力建设 | F15: =经营目标!I14 -> / | G15: =经营目标!J14 -> / | K15: “接单吧”发布，OPC 累计 注册1,300家 | M15: 合资公司模式梳理+ LEC AI MOU 签署 | P15: 合资公司注册 + 联合运营稳定 | S15: 运营手册 / 案例集 + 正式启动海外业务 | T15: =G15-SUM(H15:S15) -> #VALUE!
B16: 12 | C16: =经营目标!D15 -> 任务类指标 | D16: =经营目标!E15 -> 关注 | E16: =经营目标!F15 -> 生态联盟年度新增签约 | F16: =经营目标!I15 -> 家 | G16: =经营目标!M15 -> 4 | M16: 1 | P16: 1 | S16: 2 | T16: =G16-SUM(H16:S16) -> 0

Sheet 附件2 经营性净现金流利润编制明细2026415
E1: =SUM(F5:H5) -> 306.78245 | F1: =SUM(F15:H15) -> 167.30115 | G1: =E1-F1 -> 139.4813 | H1: =G1/E1 -> 0.45465867 | T1: 新版本
B2: 2026年经营性净现金流利润编制明细 | T2: 项目 | U2: 1月 | V2: 2月 | W2: 3月 | X2: 4月 | Y2: 5月 | Z2: 6月 | AA2: 7月 | AB2: 8月 | AC2: 9月 | AD2: 10月 | AE2: 11月 | AF2: 12月 | AG2: 合计
B3: 序号 | C3: 科目 | D3: 计量 单位 | E3: 年度目标 | F3: 年度目标分解 | R3: 备注 | T3: 学校签约节奏 | U3: 1 | V3: 1 | W3: 15 | X3: =[2]利润版预算!J$4 -> 22 | Y3: =[2]利润版预算!K$4 -> 22 | Z3: =[2]利润版预算!L$4 -> 22 | AA3: =[2]利润版预算!M$4 -> 5 | AB3: =[2]利润版预算!N$4 -> 5 | AC3: =[2]利润版预算!O$4 -> 6 | AD3: =[2]利润版预算!P$4 -> 13 | AE3: =[2]利润版预算!Q$4 -> 13 | AF3: =[2]利润版预算!R$4 -> 13 | AG3: =SUM(U3:AF3) -> 138
F4: 1月 | G4: 2月 | H4: 3月 | I4: 4月 | J4: 5月 | K4: 6月 | L4: 7月 | M4: 8月 | N4: 9月 | O4: 10月 | P4: 11月 | Q4: 12月 | T4: OPC接单金额 | AA4: =425/6 -> 70.833333 | AB4: =425/6 -> 70.833333 | AC4: =425/6 -> 70.833333 | AD4: =425/6 -> 70.833333 | AE4: =425/6 -> 70.833333 | AF4: =425/6 -> 70.833333 | AG4: =SUM(U4:AF4) -> 425
B5: 1 | C5: 营业收入 | D5: 万元 | E5: =SUM(F5:Q5) -> 2884.035 | F5: =SUM(F6) -> 18.046026 | G5: =SUM(G6) -> 18.046026 | H5: =SUM(H6) -> 270.69039 | I5: =SUM(I6) -> 354.14078 | J5: =SUM(J6) -> 354.14078 | K5: =SUM(K6) -> 354.14078 | L5: =SUM(L6) -> 226.13836 | M5: =SUM(M6) -> 256.13836 | ... Q5: =SUM(Q6) -> 258.80503
A6: =E6/E6 -> 1 | B6: 1.1 | C6: 主营业务收入 | D6: 万元 | E6: =SUM(F6:Q6) -> 2884.035 | F6: =SUM(F7:F13) -> 18.046026 | G6: =SUM(G7:G13) -> 18.046026 | H6: =SUM(H7:H13) -> 270.69039 | I6: =SUM(I7:I13) -> 354.14078 | J6: =SUM(J7:J13) -> 354.14078 | K6: =SUM(K7:K13) -> 354.14078 | L6: =SUM(L7:L13) -> 226.13836 | M6: =SUM(M7:M13) -> 256.13836 | ... Q6: =SUM(Q7:Q13) -> 258.80503 | S6: =(E6-E15)/E6 -> 0.41538859
A7: =E7/$E$6 -> 0.57855171 | C7: AI教育进校业务 | D7: 万元 | E7: =SUM(F7:Q7) -> 1668.5634 | F7: =1212/144/0.44/1.06*U3-F10 -> 13.976026 | G7: =1212/144/0.44/1.06*V3 -> 18.046026 | H7: =1212/144/0.44/1.06*W3-H13 -> 266.73 | I7: =(12*58/1.06+12*8/1.06)/3 -> 249.0566 | J7: =(12*58/1.06+12*8/1.06)/3 -> 249.0566 | K7: =(12*58/1.06+12*8/1.06)/3 -> 249.0566 | L7: =[2]利润版预算!$G5/3 -> 60.377358 | M7: =[2]利润版预算!$G5/3 -> 60.377358 | N7: =[2]利润版预算!$G5/3 -> 60.377358 | O7: =[2]利润版预算!$H5/3 -> 147.16981 | P7: =[2]利润版预算!$H5/3 -> 147.16981 | Q7: =[2]利润版预算!$H5/3 -> 147.16981 | S7: =(E7-E16)/E7 -> 0.44207334
A8: =E8/$E$6 -> 0.036121137 | C8: 师资培训与等级认证 | D8: 万元 | E8: =SUM(F8:Q8) -> 104.17462 | I8: =(9.9/1.01+4.75)/3 -> 4.8506601 | J8: =(9.9/1.01+4.75)/3 -> 4.8506601 | K8: =(9.9/1.01+4.75)/3 -> 4.8506601 | L8: =[2]利润版预算!$G6/3 -> 11.006289 | M8: =[2]利润版预算!$G6/3 -> 11.006289 | N8: =[2]利润版预算!$G6/3 -> 11.006289 | O8: =[2]利润版预算!$H6/3 -> 18.867925 | P8: =[2]利润版预算!$H6/3 -> 18.867925 | Q8: =[2]利润版预算!$H6/3 -> 18.867925 | S8: =(E8-E17)/E8 -> 0.5
A9: =E9/$E$6 -> 0.069774797 | C9: 政企AI赋能业务 | D9: 万元 | E9: =SUM(F9:Q9) -> 201.23295 | I9: =36.5/1.01/3 -> 12.046205 | J9: =36.5/1.01/3 -> 12.046205 | K9: =36.5/1.01/3 -> 12.046205 | L9: =[2]利润版预算!$G7/3 -> 22.012579 | M9: =[2]利润版预算!$G7/3 -> 22.012579 | N9: =[2]利润版预算!$G7/3 -> 22.012579 | O9: =[2]利润版预算!$H7/3 -> 33.018868 | P9: =[2]利润版预算!$H7/3 -> 33.018868 | Q9: =[2]利润版预算!$H7/3 -> 33.018868 | S9: =(E9-E18)/E9 -> 0.5
A10: =E10/$E$6 -> 0.024308906 | C10: AI研学 | D10: 万元 | E10: =SUM(F10:Q10) -> 70.107736 | F10: =4.07 -> 4.07 | I10: =50/1.06/3 -> 15.72327 | J10: =50/1.06/3 -> 15.72327 | K10: =50/1.06/3 -> 15.72327 | L10: =[2]利润版预算!$G8/3 -> 6.2893082 | M10: =[2]利润版预算!$G8/3 -> 6.2893082 | N10: =[2]利润版预算!$G8/3 -> 6.2893082 | O10: =[2]利润版预算!$H8/3 -> 0 | P10: =[2]利润版预算!$H8/3 -> 0 | Q10: =[2]利润版预算!$H8/3 -> 0 | S10: =(E10-E19)/E10 -> 0.15
A11: =E11/$E$6 -> 0.052661446 | C11: OPC生态 | D11: 万元 | E11: =SUM(F11:Q11) -> 151.87745 | I11: =(10+10)/1.01/3 -> 6.6006601 | J11: =(10+10)/1.01/3 -> 6.6006601 | K11: =(10+10)/1.01/3 -> 6.6006601 | L11: =[2]利润版预算!$G9/3 -> 15.72327 | M11: =[2]利润版预算!$G9/3 -> 15.72327 | N11: =[2]利润版预算!$G9/3 -> 15.72327 | O11: =[2]利润版预算!$H9/3 -> 28.301887 | P11: =[2]利润版预算!$H9/3 -> 28.301887 | Q11: =[2]利润版预算!$H9/3 -> 28.301887 | S11: =(E11-E20)/E11 -> 0.8
A12: =E12/$E$6 -> 0 | C12: 不良资产盘活 | D12: 万元 | E12: =SUM(F12:Q12) -> 0 | I12: =[2]利润版预算!$F10/3 -> 0 | J12: =[2]利润版预算!$F10/3 -> 0 | K12: =[2]利润版预算!$F10/3 -> 0 | L12: =[2]利润版预算!$G10/3 -> 0 | M12: =[2]利润版预算!$G10/3 -> 0 | N12: =[2]利润版预算!$G10/3 -> 0 | O12: =[2]利润版预算!$H10/3 -> 0 | P12: =[2]利润版预算!$H10/3 -> 0 | Q12: =[2]利润版预算!$H10/3 -> 0 | S12: 0
A13: =E13/$E$6 -> 0.238582 | C13: 其他业务收入 | D13: 万元 | E13: =SUM(F13:Q13) -> 688.07883 | H13: =4/1.01 -> 3.960396 | I13: =[2]利润版预算!$F12/3 -> 65.863379 | J13: =[2]利润版预算!$F12/3 -> 65.863379 | K13: =[2]利润版预算!$F12/3 -> 65.863379 | L13: =[2]利润版预算!$G12/3 -> 110.72956 | M13: =[2]利润版预算!$G12/3+30 -> 140.72956 | N13: =[2]利润版预算!$G12/3+30 -> 140.72956 | O13: =[2]利润版预算!$H12/3 -> 31.446541 | P13: =[2]利润版预算!$H12/3 -> 31.446541 | Q13: =[2]利润版预算!$H12/3 -> 31.446541 | S13: =(E13-E22)/E13 -> 0.25527006
B14: 2 | C14: 成本费用总额 | D14: 万元 | E14: =SUM(F14:Q14) -> 2882.9952 | F14: =SUM(F15,F23:F24,F27,F30,F33) -> 87.665276 | G14: =SUM(G15,G23:G24,G27,G30,G33) -> 84.732725 | H14: =SUM(H15,H23:H24,H27,H30,H33) -> 230.82644 | I14: =SUM(I15,I23:I24,I27,I30,I33) -> 297.34704 | J14: =SUM(J15,J23:J24,J27,J30,J33) -> 328.79546 | K14: =SUM(K15,K23:K24,K27,K30,K33) -> 326.86784 | L14: =SUM(L15,L23:L24,L27,L30,L33) -> 277.54891 | M14: =SUM(M15,M23:M24,M27,M30,M33) -> 225.81937 | ... Q14: =SUM(Q15,Q23:Q24,Q27,Q30,Q33) -> 333.55027
B15: 2.1 | C15: 主营业务成本 | D15: 万元 | E15: =SUM(F15:Q15) -> 1686.0397 | F15: =SUM(F16:F22) -> 7.8265747 | G15: =SUM(G16:G22) -> 10.105775 | H15: =SUM(H16:H22) -> 149.3688 | I15: =SUM(I16:I22) -> 211.35941 | J15: =SUM(J16:J22) -> 241.35941 | K15: =SUM(K16:K22) -> 241.35941 | L15: =SUM(L16:L22) -> 138.85535 | M15: =SUM(M16:M22) -> 138.85535 | ... Q15: =SUM(Q16:Q22) -> 136.03145 | U15: 1月 | V15: 2月 | W15: 3月 | X15: 4月 | Y15: 5月 | Z15: 6月 | AA15: 7月 | AB15: 8月 | AC15: 9月 | AD15: 10月 | AE15: 11月 | AF15: 12月 | AG15: 合计
C16: AI教育进校业务 | D16: 万元 | E16: =SUM(F16:Q16) -> 930.93599 | F16: =F7*0.56-F19 -> 4.3670747 | G16: =G7*0.56 -> 10.105775 | H16: =H7*0.56-H22 -> 149.3688 | I16: =[2]利润版预算!$F15/3 -> 139.4717 | J16: =[2]利润版预算!$F15/3 -> 139.4717 | K16: =[2]利润版预算!$F15/3 -> 139.4717 | L16: =[2]利润版预算!$G15/3 -> 33.811321 | M16: =[2]利润版预算!$G15/3 -> 33.811321 | N16: =[2]利润版预算!$G15/3 -> 33.811321 | O16: =[2]利润版预算!$H15/3 -> 82.415094 | P16: =[2]利润版预算!$H15/3 -> 82.415094 | Q16: =[2]利润版预算!$H15/3 -> 82.415094 | T16: 增值税 | U16: 0.8 | V16: 0 | W16: 0 | X16: =(F5+G5+H5)*0.01 -> 3.0678245 | Y16: =(I5-I15)*0.06 -> 8.5668822 | Z16: =(J5-J15)*0.06 -> 6.7668822 | AA16: =(K5-K15)*0.06 -> 6.7668822 | AB16: =(L5-L15)*0.06 -> 5.2369811 | AC16: =(M5-M15)*0.06 -> 7.0369811 | AD16: =(N5-N15)*0.06 -> 7.0369811 | AE16: =(O5-O15)*0.06 -> 7.3664151 | AF16: =(P5-P15)*0.06 -> 7.3664151 | AG16: =SUM(U16:AF16) -> 60.012245
C17: 师资培训与等级认证 | D17: 万元 | E17: =SUM(F17:Q17) -> 52.087311 | I17: =[2]利润版预算!$F16/3 -> 2.42533 | J17: =[2]利润版预算!$F16/3 -> 2.42533 | K17: =[2]利润版预算!$F16/3 -> 2.42533 | L17: =[2]利润版预算!$G16/3 -> 5.5031447 | M17: =[2]利润版预算!$G16/3 -> 5.5031447 | N17: =[2]利润版预算!$G16/3 -> 5.5031447 | O17: =[2]利润版预算!$H16/3 -> 9.4339623 | P17: =[2]利润版预算!$H16/3 -> 9.4339623 | Q17: =[2]利润版预算!$H16/3 -> 9.4339623
C18: 政企AI赋能业务 | D18: 万元 | E18: =SUM(F18:Q18) -> 100.61648 | I18: =[2]利润版预算!$F17/3 -> 6.0231023 | J18: =[2]利润版预算!$F17/3 -> 6.0231023 | K18: =[2]利润版预算!$F17/3 -> 6.0231023 | L18: =[2]利润版预算!$G17/3 -> 11.006289 | M18: =[2]利润版预算!$G17/3 -> 11.006289 | N18: =[2]利润版预算!$G17/3 -> 11.006289 | O18: =[2]利润版预算!$H17/3 -> 16.509434 | P18: =[2]利润版预算!$H17/3 -> 16.509434 | Q18: =[2]利润版预算!$H17/3 -> 16.509434
C19: AI研学 | D19: 万元 | E19: =SUM(F19:Q19) -> 59.591575 | F19: =F10*0.85 -> 3.4595 | I19: =[2]利润版预算!$F18/3 -> 13.36478 | J19: =[2]利润版预算!$F18/3 -> 13.36478 | K19: =[2]利润版预算!$F18/3 -> 13.36478 | L19: =[2]利润版预算!$G18/3 -> 5.3459119 | M19: =[2]利润版预算!$G18/3 -> 5.3459119 | N19: =[2]利润版预算!$G18/3 -> 5.3459119 | O19: =[2]利润版预算!$H18/3 -> 0 | P19: =[2]利润版预算!$H18/3 -> 0 | Q19: =[2]利润版预算!$H18/3 -> 0
C20: OPC生态 | D20: 万元 | E20: =SUM(F20:Q20) -> 30.37549 | I20: =[2]利润版预算!$F19/3 -> 1.320132 | J20: =[2]利润版预算!$F19/3 -> 1.320132 | K20: =[2]利润版预算!$F19/3 -> 1.320132 | L20: =[2]利润版预算!$G19/3 -> 3.1446541 | M20: =[2]利润版预算!$G19/3 -> 3.1446541 | N20: =[2]利润版预算!$G19/3 -> 3.1446541 | O20: =[2]利润版预算!$H19/3 -> 5.6603774 | P20: =[2]利润版预算!$H19/3 -> 5.6603774 | Q20: =[2]利润版预算!$H19/3 -> 5.6603774
C21: 不良资产盘活 | D21: 万元 | E21: =SUM(F21:Q21) -> 0 | F21: =F8*0.85 -> 0 | G21: =G8*0.85 -> 0 | H21: =H8*0.85 -> 0 | I21: =[2]利润版预算!$F20/3 -> 0 | J21: =[2]利润版预算!$F20/3 -> 0 | K21: =[2]利润版预算!$F20/3 -> 0 | L21: =[2]利润版预算!$G20/3 -> 0 | M21: =[2]利润版预算!$G20/3 -> 0 | N21: =[2]利润版预算!$G20/3 -> 0 | O21: =[2]利润版预算!$H20/3 -> 0 | P21: =[2]利润版预算!$H20/3 -> 0 | Q21: =[2]利润版预算!$H20/3 -> 0 | T21: 城建税及附加 | U21: =U16*0.1 -> 0.08 | V21: 0 | W21: 0 | X21: =X16*0.1 -> 0.30678245 | Y21: =Y16*0.1 -> 0.85668822 | Z21: =Z16*0.1 -> 0.67668822 | AA21: =AA16*0.1 -> 0.67668822 | AB21: =AB16*0.1 -> 0.52369811 | AC21: =AC16*0.1 -> 0.70369811 | AD21: =AD16*0.1 -> 0.70369811 | AE21: =AE16*0.1 -> 0.73664151 | AF21: =AF16*0.1 -> 0.73664151 | AG21: =SUM(U21:AF21) -> 6.0012245
C22: 其他业务 | D22: 万元 | E22: =SUM(F22:Q22) -> 512.43291 | F22: =F9*0.65 -> 0 | G22: =G9*0.65 -> 0 | I22: =[2]利润版预算!$F22/3+2.65 -> 48.754365 | J22: =[2]利润版预算!$F22/3+2.65+30 -> 78.754365 | K22: =[2]利润版预算!$F22/3+2.65+30 -> 78.754365 | L22: =[2]利润版预算!$G22/3 -> 80.044025 | M22: =[2]利润版预算!$G22/3 -> 80.044025 | N22: =[2]利润版预算!$G22/3 -> 80.044025 | O22: =[2]利润版预算!$H22/3 -> 22.012579 | P22: =[2]利润版预算!$H22/3 -> 22.012579 | Q22: =[2]利润版预算!$H22/3 -> 22.012579 | T22: 合计 | U22: =U16+U21 -> 0.88 | V22: =V16+V21 -> 0 | W22: =W16+W21 -> 0 | X22: =X16+X21 -> 3.3746069 | Y22: =Y16+Y21 -> 9.4235704 | Z22: =Z16+Z21 -> 7.4435704 | AA22: =AA16+AA21 -> 7.4435704 | AB22: =AB16+AB21 -> 5.7606792 | ... AF22: =AF16+AF21 -> 8.1030566 | AG22: =SUM(U22:AF22) -> 66.013469
B23: 2.3 | C23: 税金及附加 | D23: 万元 | E23: =SUM(F23:Q23) -> 6.4412245 | F23: =U21 -> 0.08 | G23: =V21 -> 0 | H23: =W21 -> 0 | I23: =X21 -> 0.30678245 | J23: =Y21+0.22 -> 1.0766882 | K23: =Z21+0.22 -> 0.89668822 | L23: =AA21 -> 0.67668822 | M23: =AB21 -> 0.52369811 | N23: =AC21 -> 0.70369811 | O23: =AD21 -> 0.70369811 | P23: =AE21 -> 0.73664151 | Q23: =AF21 -> 0.73664151
B24: 2.4 | C24: 销售费用 | D24: 万元 | E24: =SUM(F24:Q24) -> 273.51774 | F24: =[3]部门月度费用汇总!C$30 -> 10.905984 | G24: =[3]部门月度费用汇总!D$30 -> 10.924317 | H24: =[3]部门月度费用汇总!E$30 -> 15.337651 | I24: =[3]部门月度费用汇总!F$30-50-36 -> 15.189317 | J24: =[3]部门月度费用汇总!G$30 -> 10.939317 | K24: =[3]部门月度费用汇总!H$30 -> 11.019317 | L24: =[3]部门月度费用汇总!I$30 -> 21.286905 | M24: =[3]部门月度费用汇总!J$30 -> 11.276905 | N24: =[3]部门月度费用汇总!K$30 -> 11.627005 | O24: =[3]部门月度费用汇总!L$30 -> 21.307005 | P24: =[3]部门月度费用汇总!M$30 -> 11.817005 | Q24: =[3]部门月度费用汇总!N$30 -> 121.88701
C25: 其中：折旧费 | D25: 万元 | E25: =SUM(F25:Q25) -> 0
C26: 摊销费 | D26: 万元 | E26: =SUM(F26:Q26) -> 0
B27: 2.5 | C27: 管理费用 | D27: 万元 | E27: =SUM(F27:Q27) -> 648.05234 | F27: =[3]部门月度费用汇总!C$31 -> 49.077442 | G27: =[3]部门月度费用汇总!D$31 -> 43.581157 | H27: =[3]部门月度费用汇总!E$31 -> 45.862485 | I27: =[3]部门月度费用汇总!F$31 -> 49.392587 | J27: =([3]部门月度费用汇总!G$31)+9 -> 54.425585 | K27: =([3]部门月度费用汇总!H$31)+9 -> 52.51532 | L27: =([3]部门月度费用汇总!I$31)+9 -> 78.867157 | M27: =([3]部门月度费用汇总!J$31)+9 -> 54.000557 | N27: =([3]部门月度费用汇总!K$31)+9 -> 55.010492 | O27: =([3]部门月度费用汇总!L$31)+9 -> 55.920357 | P27: =([3]部门月度费用汇总!M$31)+9 -> 55.677092 | Q27: =([3]部门月度费用汇总!N$31)+9 -> 53.722111
C28: 其中：折旧费 | D28: 万元 | E28: =SUM(F28:Q28) -> 0
C29: 摊销费 | D29: 万元 | E29: =SUM(F29:Q29) -> 0
B30: 2.6 | C30: 研发费用 | D30: 万元 | E30: =SUM(F30:Q30) -> 242.14398 | F30: =[3]部门月度费用汇总!C$32 -> 18.658776 | G30: =[3]部门月度费用汇总!D$32 -> 18.831476 | H30: =[3]部门月度费用汇总!E$32 -> 18.762076 | I30: =[3]部门月度费用汇总!F$32 -> 18.946576 | J30: =[3]部门月度费用汇总!G$32 -> 18.446776 | K30: =[3]部门月度费用汇总!H$32 -> 18.477376 | L30: =[3]部门月度费用汇总!I$32 -> 35.26308 | M30: =[3]部门月度费用汇总!J$32 -> 18.56313 | ... Q30: =[3]部门月度费用汇总!N$32 -> 18.57333
C31: 其中：折旧费 | D31: 万元 | E31: =SUM(F31:Q31) -> 0
C32: 摊销费 | D32: 万元 | E32: =SUM(F32:Q32) -> 0
B33: 2.7 | C33: 财务费用 | D33: 万元 | E33: =SUM(F33:Q33) -> 26.800125 | F33: 1.1165 | G33: 1.29 | H33: 1.495425 | I33: 2.1523694 | J33: 2.5476819 | K33: 2.5997355 | L33: 2.5997355 | M33: 2.5997355 | N33: 2.5997355 | O33: 2.5997355 | P33: 2.5997355 | Q33: 2.5997355
C34: 其中：集团内 | D34: 万元 | E34: =SUM(F34:Q34) -> 0
B35: 3 | C35: 营业利润 | D35: 万元 | E35: =SUM(F35:Q35) -> 1.0398117 | F35: =F5-F14 -> -69.61925 | G35: =G5-G14 -> -66.686698 | H35: =H5-H14 -> 39.863959 | I35: =I5-I14 -> 56.793738 | J35: =J5-J14 -> 25.345322 | K35: =K5-K14 -> 27.272933 | L35: =L5-L14 -> -51.410547 | M35: =M5-M14 -> 30.318993 | ... Q35: =Q5-Q14 -> -74.745238
C36: 加：营业外收入 | D36: 万元 | E36: =SUM(F36:Q36) -> 0
C37: 减：营业外支出 | D37: 万元 | E37: =SUM(F37:Q37) -> 0
B38: 4 | C38: 利润总额 | D38: 万元 | E38: =SUM(F38:Q38) -> 1.0398117 | F38: =F35-F37+F36 -> -69.61925 | G38: =G35-G37+G36 -> -66.686698 | H38: =H35-H37+H36 -> 39.863959 | I38: =I35-I37+I36 -> 56.793738 | J38: =J35-J37+J36 -> 25.345322 | K38: =K35-K37+K36 -> 27.272933 | L38: =L35-L37+L36 -> -51.410547 | M38: =M35-M37+M36 -> 30.318993 | ... Q38: =Q35-Q37+Q36 -> -74.745238
C39: 减：所得税费用 | D39: 万元 | E39: =SUM(F39:Q39) -> 0
B40: 5 | C40: 净利润 | D40: 万元 | E40: =SUM(F40:Q40) -> 1.0398117 | F40: =F38-F39 -> -69.61925 | G40: =G38-G39 -> -66.686698 | H40: =H38-H39 -> 39.863959 | I40: =I38-I39 -> 56.793738 | J40: =J38-J39 -> 25.345322 | K40: =K38-K39 -> 27.272933 | L40: =L38-L39 -> -51.410547 | M40: =M38-M39 -> 30.318993 | ... Q40: =Q38-Q39 -> -74.745238
...

Sheet 附件3 经营性资金计划 2026415
E1: 回款进度预估 | F1: 未回款 | G1: 未回款 | H1: 1月 | I1: 2月 | J1: 3月/2 | K1: 4月 | L1: 5月 | M1: 6月 | N1: 7月+8月 | O1: 9月 | P1: 10月+3月/2 | Q1: 11月+12月/2
B2: 2026年经营性资金编制明细
B3: 序号 | C3: 科目 | D3: 计量 单位 | E3: 年度合计 | F3: 年度计划分解
F4: 1月 | G4: 2月 | H4: 3月 | I4: 4月 | J4: 5月 | K4: 6月 | L4: 7月 | M4: 8月 | N4: 9月 | O4: 10月 | P4: 11月 | Q4: 12月
B5: 1 | C5: 经营活动现金流入 | D5: 万元 | E5: =+E6+E10+E11 -> 3003.0213 | F5: =+F6+F10+F11 -> 0 | G5: =+G6+G10+G11 -> 0 | H5: =+H6+H10+H11 -> 19.846487 | I5: =+I6+I10+I11 -> 101.23585 | J5: =+J6+J10+J11 -> 235.9345 | K5: =+K6+K10+K11 -> 352.78302 | L5: =+L6+L10+L11 -> 439.70667 | ... Q5: =+Q6+Q10+Q11 -> 395.13613
B6: 1.1 | C6: 销售商品、提供劳务收到的现金 | D6: 万元 | E6: =SUM(E7:E9) -> 3001.4013 | F6: =F7+F8+F9 -> 0 | G6: =G7+G8+G9 -> 0 | H6: =H7+H8+H9 -> 18.226487 | I6: =I7+I8+I9 -> 101.23585 | J6: =J7+J8+J9 -> 235.9345 | K6: =K7+K8+K9 -> 352.78302 | L6: =L7+L8+L9 -> 439.70667 | M6: =M7+M8+M9 -> 501.50667 | ... Q6: =Q7+Q8+Q9 -> 395.13613
C7: 其中：主营业务回款 | D7: 万元 | E7: =SUM(F7:Q7) -> 1687.8631 | H7: ='附件2 经营性净现金流利润编制明细2026415'!F7*1.01 -> 14.115787 | J7: ='附件2 经营性净现金流利润编制明细2026415'!H7*1.01/2 -> 134.69865 | K7: ='附件2 经营性净现金流利润编制明细2026415'!I7*1.01 -> 251.54717 | L7: ='附件2 经营性净现金流利润编制明细2026415'!J7*1.06 -> 264 | M7: ='附件2 经营性净现金流利润编制明细2026415'!K7*1.06 -> 264 | N7: =('附件2 经营性净现金流利润编制明细2026415'!L7+'附件2 经营性净现金流利润编制明细2026415'!M7)*1.06 -> 128 | O7: =('附件2 经营性净现金流利润编制明细2026415'!N7)*1.06 -> 64 | P7: =('附件2 经营性净现金流利润编制明细2026415'!O7)*1.06+'附件2 经营性净现金流利润编制明细2026415'!H7/2*1.01 -> 290.69865 | Q7: =('附件2 经营性净现金流利润编制明细2026415'!P7+'附件2 经营性净现金流利润编制明细2026415'!Q7/2+40.38)*1.06 -> 276.8028
C8: 其他业务回款 | D8: 万元 | E8: =SUM(F8:Q8) -> 1313.5382 | H8: =SUM('附件2 经营性净现金流利润编制明细2026415'!F8:F13)*1.01 -> 4.1107 | I8: =SUM('附件2 经营性净现金流利润编制明细2026415'!I9:I13)*1.01 -> 101.23585 | J8: =SUM('附件2 经营性净现金流利润编制明细2026415'!J9:J13)*1.01 -> 101.23585 | K8: =SUM('附件2 经营性净现金流利润编制明细2026415'!K9:K13)*1.01 -> 101.23585 | L8: =SUM('附件2 经营性净现金流利润编制明细2026415'!L8:L13)*1.06 -> 175.70667 | M8: =SUM('附件2 经营性净现金流利润编制明细2026415'!M8:M13)*1.06+30 -> 237.50667 | N8: =SUM('附件2 经营性净现金流利润编制明细2026415'!N8:N13)*1.06+30 -> 237.50667 | O8: =SUM('附件2 经营性净现金流利润编制明细2026415'!O8:O13)*1.06 -> 118.33333 | P8: =SUM('附件2 经营性净现金流利润编制明细2026415'!P8:P13)*1.06 -> 118.33333 | Q8: =SUM('附件2 经营性净现金流利润编制明细2026415'!Q8:Q13)*1.06 -> 118.33333
C9: …… | D9: 万元
B10: 1.2 | C10: 收到的税费返还 | D10: 万元 | E10: =1.8*6*0.15 -> 1.62 | H10: 1.62
B11: 1.3 | C11: 收到其他与经营活动有关的现金 | D11: 万元
C12: …… | D12: 万元
B13: 2 | C13: 经营活动现金流出 | D13: 万元 | E13: =+E14+E18+E19+E20 -> 2988.8499 | F13: =+F14+F18+F19+F20 -> 78.58 | G13: =+G14+G18+G19+G20 -> 86.1 | H13: =+H14+H18+H19+H20 -> 103.2 | I13: =+I14+I18+I19+I20 -> 220.97814 | J13: =+J14+J18+J19+J20 -> 300.61182 | K13: =+K14+K18+K19+K20 -> 361.86699 | L13: =+L14+L18+L19+L20 -> 394.03024 | ... Q13: =+Q14+Q18+Q19+Q20 -> 297.87639
B14: 2.1 | C14: 购买商品、接受劳务支付的现金 | D14: 万元 | E14: =SUM(F14:Q14) -> 1849.7464 | F14: =F15+F16 -> 4.5 | G14: =G15+G16 -> 4.5 | H14: =H15+H16 -> 30 | I14: =I15+I16 -> 131.96353 | J14: =J15+J16 -> 205.88825 | K14: =K15+K16 -> 271.32342 | L14: =L15+L16 -> 259.18667 | M14: =M15+M16 -> 259.18667 | ... Q14: =Q15+Q16 -> 187.87333
C15: 其中：主营业务采购成本 | D15: 万元 | E15: =SUM(F15:Q15) -> 1014.1354 | F15: =(3+1.5)*'附件2 经营性净现金流利润编制明细2026415'!U3 -> 4.5 | G15: =(3+1.5)*'附件2 经营性净现金流利润编制明细2026415'!V3 -> 4.5 | H15: =(0.5+1.5)*'附件2 经营性净现金流利润编制明细2026415'!W3 -> 30 | I15: =I7*0.56+('附件2 经营性净现金流利润编制明细2026415'!H16-39)*0.56 -> 61.806528 | J15: =J7*0.56 -> 75.431244 | K15: =K7*0.56 -> 140.86642 | L15: =L7*0.56 -> 147.84 | M15: =M7*0.56 -> 147.84 | N15: =N7*0.56 -> 71.68 | O15: =O7*0.56 -> 35.84 | P15: =P7*0.56 -> 162.79124 | Q15: 131.04
C16: 其他业务采购成本 | D16: 万元 | E16: =SUM(F16:Q16) -> 835.61101 | I16: =SUM('附件2 经营性净现金流利润编制明细2026415'!I18:I22)*1.01 -> 70.157003 | J16: =SUM('附件2 经营性净现金流利润编制明细2026415'!J18:J22)*1.01+30 -> 130.457 | K16: =SUM('附件2 经营性净现金流利润编制明细2026415'!K18:K22)*1.01+30 -> 130.457 | L16: =SUM('附件2 经营性净现金流利润编制明细2026415'!L17:L22)*1.06 -> 111.34667 | M16: =SUM('附件2 经营性净现金流利润编制明细2026415'!M17:M22)*1.06 -> 111.34667 | N16: =SUM('附件2 经营性净现金流利润编制明细2026415'!N17:N22)*1.06 -> 111.34667 | O16: =SUM('附件2 经营性净现金流利润编制明细2026415'!O17:O22)*1.06 -> 56.833333 | P16: =SUM('附件2 经营性净现金流利润编制明细2026415'!P17:P22)*1.06 -> 56.833333 | Q16: =SUM('附件2 经营性净现金流利润编制明细2026415'!Q17:Q22)*1.06 -> 56.833333
C17: …… | D17: 万元
B18: 2.2 | C18: 支付给职工及为职工支付的现金 | D18: 万元 | E18: =SUM(F18:Q18) -> 783 | F18: =6+47.2 -> 53.2 | G18: 56 | H18: 56 | I18: 57 | J18: 56.5 | K18: 68 | L18: =((50+40)+6)+9 -> 105 | M18: 65 | N18: 68 | O18: 65 | P18: 65 | Q18: =(0.3+59)+9 -> 68.3
B19: 2.3 | C19: 支付的各项税费 | D19: 万元 | E19: =SUM(F19:Q19) -> 66.013469 | F19: ='附件2 经营性净现金流利润编制明细2026415'!U22 -> 0.88 | G19: ='附件2 经营性净现金流利润编制明细2026415'!V22 -> 0 | H19: ='附件2 经营性净现金流利润编制明细2026415'!W22 -> 0 | I19: ='附件2 经营性净现金流利润编制明细2026415'!X22 -> 3.3746069 | J19: ='附件2 经营性净现金流利润编制明细2026415'!Y22 -> 9.4235704 | K19: ='附件2 经营性净现金流利润编制明细2026415'!Z22 -> 7.4435704 | L19: ='附件2 经营性净现金流利润编制明细2026415'!AA22 -> 7.4435704 | M19: ='附件2 经营性净现金流利润编制明细2026415'!AB22 -> 5.7606792 | ... Q19: ='附件2 经营性净现金流利润编制明细2026415'!AF22 -> 8.1030566
B20: 2.4 | C20: 支付其他与经营活动有关的现金 | D20: 万元 | E20: =SUM(F20:Q20) -> 290.09 | F20: =10+10 -> 20 | G20: =7.2+13.4+5 -> 25.6 | H20: =7.2+10 -> 17.2 | I20: =13.9+10+84+6.74-50-36 -> 28.64 | J20: =15.4+13.4 -> 28.8 | K20: 15.1 | L20: =10+12.4 -> 22.4 | M20: =12.4+2.03+13.4 -> 27.83 | N20: 12.4 | O20: =10+23.12 -> 33.12 | P20: =12+13.4 -> 25.4 | Q20: =10+23.6 -> 33.6
C21: …… | D21: 万元
B22: 3 | C22: 经营活动现金净额 | D22: 万元 | E22: =+E5-E13 -> 14.171394 | F22: =+F5-F13 -> -78.58 | G22: =+G5-G13 -> -86.1 | H22: =+H5-H13 -> -83.353513 | I22: =+I5-I13 -> -119.74229 | J22: =+J5-J13 -> -64.677319 | K22: =+K5-K13 -> -9.0839698 | L22: =+L5-L13 -> 45.67643 | ... Q22: =+Q5-Q13 -> 97.259743
F23: 80 | G23: 40 | H23: 150 | I23: 200 | J23: 50
B28: 序号 | C28: 科目 | D28: 计量 单位 | E28: 年度合计 | F28: 年度计划分解-Q2预测
F29: 1月 | G29: 2月 | H29: 3月 | I29: 4月 | J29: 5月 | K29: 6月 | L29: 7月 | M29: 8月 | N29: 9月 | O29: 10月 | P29: 11月 | Q29: 12月
B30: 1 | C30: 经营活动现金流入 | D30: 万元 | E30: =+E31+E35+E36 -> 2249.3609 | F30: =+F31+F35+F36 -> 0 | G30: =+G31+G35+G36 -> 0 | H30: =+H31+H35+H36 -> 19.846487 | I30: =+I31+I35+I36 -> 48.226487 | J30: =+J31+J35+J36 -> 60 | K30: =+K31+K35+K36 -> 54.67946 | L30: =+L31+L35+L36 -> 286.93182 | ... Q30: =+Q31+Q35+Q36 -> 395.13613 | R30: =SUM(I30:K30) -> 162.90595 | S30: =SUM(L30:N30) -> 954.55 | T30: =SUM(O30:Q30) -> 1112.0584
B31: 1.1 | C31: 销售商品、提供劳务收到的现金 | D31: 万元 | E31: =SUM(F31:Q31) -> 2247.7409 | F31: 0 | G31: 0 | H31: 18.226487 | I31: =18.2264865637507+30 -> 48.226487 | J31: 60 | K31: =H31*3 -> 54.67946 | L31: 286.93182 | M31: 292.23182 | N31: 375.38636 | O31: 290.11182 | P31: 426.81047 | Q31: =Q6 -> 395.13613
C32: 其中：主营业务回款 | D32: 万元 | E32: =SUM(F32:Q32) -> 2129.4075 | H32: 18.226487 | I32: =18.2264865637507+30 -> 48.226487 | J32: 60 | K32: =H32*3 -> 54.67946 | L32: 286.93182 | M32: 292.23182 | N32: 375.38636 | O32: 290.11182 | P32: 426.81047 | Q32: =Q7 -> 276.8028
C33: 其他业务回款 | D33: 万元 | E33: =SUM(F33:Q33) -> 0
C34: …… | D34: 万元 | E34: =SUM(F34:Q34) -> 0
B35: 1.2 | C35: 收到的税费返还 | D35: 万元 | E35: =SUM(F35:Q35) -> 1.62 | H35: 1.62
B36: 1.3 | C36: 收到其他与经营活动有关的现金 | D36: 万元 | E36: =SUM(F36:Q36) -> 0
C37: …… | D37: 万元 | E37: =SUM(F37:Q37) -> 0
B38: 2 | C38: 经营活动现金流出 | D38: 万元 | E38: =+E39+E43+E44+E45 -> 2361.4539 | F38: =+F39+F43+F44+F45 -> 78.58 | G38: =+G39+G43+G44+G45 -> 81.6 | H38: =+H39+H43+H44+H45 -> 66.2 | I38: =+I39+I43+I44+I45 -> 122.02144 | J38: =+J39+J43+J44+J45 -> 138.38113 | K38: =+K39+K43+K44+K45 -> 121.58135 | L38: =+L39+L43+L44+L45 -> 295.99217 | ... Q38: =+Q39+Q43+Q44+Q45 -> 295.32194 | R38: =SUM(I38:K38) -> 381.98392 | S38: =SUM(L38:N38) -> 851.91128 | T38: =SUM(O38:Q38) -> 901.17871
B39: 2.1 | C39: 购买商品、接受劳务支付的现金 | D39: 万元 | E39: =SUM(F39:Q39) -> 1213.028 | F39: 4.5 | I39: =I31*0.56 -> 27.006832 | J39: =J31*0.56 -> 33.6 | K39: =K31*0.56 -> 30.620497 | L39: =L31*0.56 -> 160.68182 | M39: =M31*0.56 -> 163.64982 | N39: =N31*0.56 -> 210.21636 | O39: =O31*0.56 -> 162.46262 | P39: =P31*0.56 -> 239.01386 | Q39: =Q31*0.56-40 -> 181.27623 | R39: =SUM(I39:K39) -> 91.22733 | S39: =SUM(L39:N39) -> 534.548 | T39: =SUM(O39:Q39) -> 582.75271
C40: 其中：主营业务采购成本 | D40: 万元 | E40: =SUM(F40:Q40) -> 1146.7614 | F40: 4.5 | I40: =I32*0.56 -> 27.006832 | J40: =J32*0.56 -> 33.6 | K40: =K32*0.56 -> 30.620497 | L40: =L32*0.56 -> 160.68182 | M40: =M32*0.56 -> 163.64982 | N40: =N32*0.56 -> 210.21636 | O40: =O32*0.56 -> 162.46262 | P40: =P32*0.56 -> 239.01386 | Q40: =Q32*0.56-40 -> 115.00957
C41: 其他业务采购成本 | D41: 万元 | E41: =SUM(F41:Q41) -> 0
C42: …… | D42: 万元 | E42: =SUM(F42:Q42) -> 0
B43: 2.2 | C43: 支付给职工及为职工支付的现金 | D43: 万元 | E43: =SUM(F43:Q43) -> 792 | F43: 53.2 | G43: 56 | H43: 56 | I43: 57 | J43: =56.5+9 -> 65.5 | K43: =59+9 -> 68 | L43: 105 | M43: 65 | N43: 68 | O43: 65 | P43: 65 | Q43: 68.3 | R43: =SUM(I43:K43) -> 190.5 | S43: =SUM(L43:N43) -> 238 | T43: =SUM(O43:Q43) -> 198.3
B44: 2.3 | C44: 支付的各项税费 | D44: 万元 | E44: =SUM(F44:Q44) -> 67.335867 | F44: 0.88 | G44: 0 | H44: 0 | I44: 3.3746069 | J44: 10.481132 | K44: 7.8608491 | L44: 7.9103491 | M44: 4.1494366 | N44: 4.6734932 | O44: 7.9301491 | P44: 7.9301491 | Q44: 12.145702 | R44: =SUM(I44:K44) -> 21.716588 | S44: =SUM(L44:N44) -> 16.733279 | T44: =SUM(O44:Q44) -> 28.006
...

Sheet 逻辑-利润版预算
A1: 序号 | B1: 科目 | C1: 计量 单位 | D1: 年度目标 | E1: 年度目标分解
E2: Q1 | F2: Q2 | G2: Q3 | H2: Q4 | J2: 4月 | K2: 5月 | L2: 6月 | M2: 7月 | N2: 8月 | O2: 9月 | P2: 10月 | Q2: 11月 | R2: 12月 | S2: Q1
A3: 1 | B3: 营业收入 | C3: 万元 | D3: =SUM(E3:H3) -> 2824.035 | E3: =SUM(E4,E12) -> 306.78245 | F3: =SUM(F4,F12) -> 1062.4223 | G3: =SUM(G4,G12) -> 678.41509 | H3: =SUM(H4,H12) -> 776.41509 | I3: =2932-D3 -> 107.96503
A4: 1.1 | B4: 主营业务收入 | C4: 万元 | D4: =SUM(E4:H4) -> 2195.9561 | E4: =SUM(E5:E11) -> 302.82205 | F4: =SUM(F5:F11) -> 864.8322 | G4: =SUM(G5:G11) -> 346.22642 | H4: =SUM(H5:H11) -> 682.07547 | J4: =66/3 -> 22 | K4: =66/3 -> 22 | L4: =66/3 -> 22 | M4: 5 | N4: 5 | O4: 6 | P4: =39/3 -> 13 | Q4: =39/3 -> 13 | R4: =39/3 -> 13 | S4: 17 | T4: =SUM(J4:S4) -> 138
B5: AI教育进校业务 | C5: 万元 | D5: =SUM(E5:H5) -> 1668.5634 | E5: =SUM('[2]附件2 经营性净现金流利润编制明细'!F7:H7)-4/1.01-4.07 -> 298.75205 | F5: =12*58/1.06+12*8/1.06 -> 747.16981 | G5: =12*12/1.06+12*4/1.06 -> 181.13208 | H5: =12*24/1.06+12*15/1.06 -> 441.50943 | J5: =D5/$D$3 -> 0.59084374
B6: 师资培训与等级认证 | C6: 万元 | D6: =SUM(E6:H6) -> 104.17462 | F6: =9.9/1.01+4.75 -> 14.55198 | G6: =35/1.06 -> 33.018868 | H6: =(25*2+10)/1.06 -> 56.603774 | J6: =D6/$D$3 -> 0.036888574
B7: 政企AI赋能培训 | C7: 万元 | D7: =SUM(E7:H7) -> 201.23295 | F7: =36.5/1.01 -> 36.138614 | G7: =70/1.06 -> 66.037736 | H7: =105/1.06 -> 99.056604 | J7: =D7/$D$3 -> 0.071257246
B8: AI研学 | C8: 万元 | D8: =SUM(E8:H8) -> 70.107736 | E8: 4.07 | F8: =50/1.06 -> 47.169811 | G8: =20/1.06 -> 18.867925 | J8: =D8/$D$3 -> 0.024825378
B9: OPC生态 | C9: 万元 | D9: =SUM(E9:H9) -> 151.87745 | F9: =10/1.01+10/1.01 -> 19.80198 | G9: =20/1.06+30/1.06 -> 47.169811 | H9: =30/1.06+60/1.06 -> 84.90566 | J9: =D9/$D$3 -> 0.053780301
B10: 不良资产盘活 | C10: 万元 | D10: =SUM(E10:H10) -> 0 | J10: =D10/$D$3 -> 0
C11: 万元 | D11: =SUM(E11:H11) -> 0 | J11: =D11/$D$3 -> 0
A12: 1.2 | B12: 其他业务收入-智创服务 | C12: 万元 | D12: =SUM(E12:H12) -> 628.07883 | E12: =4/1.01 -> 3.960396 | F12: =5/1.01+4/1.01+200/1.06 -> 197.59014 | G12: =(350)/1.06+2 -> 332.18868 | H12: =(100)/1.06 -> 94.339623 | J12: =D12/$D$3 -> 0.22240477
A13: 2 | B13: 成本总额 | C13: 万元 | D13: =SUM(E13:H13) -> 1626.0463 | E13: =SUM(E14,E22) -> 175.25767 | F13: =SUM(F14,F22) -> 626.12822 | G13: =SUM(G14,G22) -> 416.56604 | H13: =SUM(H14,H22) -> 408.09434 | I13: =1666-D13 -> 39.95373
A14: 2.1 | B14: 主营业务成本 | C14: 万元 | D14: =SUM(E14:H14) -> 1181.5634 | E14: =SUM(E15:E21) -> 175.25767 | F14: =SUM(F15:F21) -> 487.81513 | G14: =SUM(G15:G21) -> 176.43396 | H14: =SUM(H15:H21) -> 342.0566 | J14: =10+30+60 -> 100
B15: AI教育进校业务 | C15: 万元 | D15: =SUM(E15:H15) -> 938.89251 | E15: =SUM('[2]附件2 经营性净现金流利润编制明细'!F17:H17) -> 171.79817 | F15: =F5*56% -> 418.41509 | G15: =G5*56% -> 101.43396 | H15: =H5*56% -> 247.24528
B16: 师资培训与等级认证 | C16: 万元 | D16: =SUM(E16:H16) -> 52.087311 | E16: =E6*0.5 -> 0 | F16: =F6*0.5 -> 7.2759901 | G16: =G6*0.5 -> 16.509434 | H16: =H6*0.5 -> 28.301887
B17: 政企AI赋能培训 | C17: 万元 | D17: =SUM(E17:H17) -> 100.61648 | E17: =E7*0.5 -> 0 | F17: =F7*0.5 -> 18.069307 | G17: =G7*0.5 -> 33.018868 | H17: =H7*0.5 -> 49.528302
B18: AI研学 | C18: 万元 | D18: =SUM(E18:H18) -> 59.591575 | E18: =E8*0.85 -> 3.4595 | F18: =F8*0.85 -> 40.09434 | G18: =G8*0.85 -> 16.037736 | H18: =H8*0.85 -> 0
B19: OPC生态 | C19: 万元 | D19: =SUM(E19:H19) -> 30.37549 | E19: =E9*0.1 -> 0 | F19: =F9*0.2 -> 3.960396 | G19: =G9*0.2 -> 9.4339623 | H19: =H9*0.2 -> 16.981132
B20: 不良资产盘活 | C20: 万元 | D20: =SUM(E20:H20) -> 0
C21: 万元 | D21: =SUM(E21:H21) -> 0 | K21: =-9.9/1.01-4.75 -> -14.55198
A22: 2.2 | B22: 其他业务成本 | C22: 万元 | D22: =SUM(E22:H22) -> 444.48291 | F22: =F12*0.7 -> 138.3131 | G22: =G12*0.7+7.6 -> 240.13208 | H22: =H12*0.7 -> 66.037736
A23: 3 | B23: 毛利 | C23: 万元 | D23: =SUM(E23:H23) -> 1197.9887 | E23: =E3-E13 -> 131.52478 | F23: =F3-F13 -> 436.29411 | G23: =G3-G13 -> 261.84906 | H23: =H3-H13 -> 368.32075
A24: 4 | B24: 三费+财务费用 | C24: 万元 | D24: =SUM(E24:H24) -> 1190.4942 | E24: =SUM('[2]附件2 经营性净现金流利润编制明细'!F26:H26,'[2]附件2 经营性净现金流利润编制明细'!F29:H29,'[2]附件2 经营性净现金流利润编制明细'!F32:H32,'[2]附件2 经营性净现金流利润编制明细'!F35:H35) -> 235.84329 | F24: =SUM('[2]附件2 经营性净现金流利润编制明细'!I26:K35) -> 342.44196 | G24: =SUM('[2]附件2 经营性净现金流利润编制明细'!L26:N35) -> 313.38957 | H24: =SUM('[2]附件2 经营性净现金流利润编制明细'!O26:Q35)-37-50 -> 298.81937
A25: 5 | B25: 税费附加 | C25: 万元 | D25: =SUM(E25:H25) -> 6.4426667 | F25: =7.48/3 -> 2.4933333 | G25: =7.48/3 -> 2.4933333 | H25: =7.48/5-0.04 -> 1.456 | I25: =D23-D24+60 -> 67.494514
A26: 6 | B26: 利润总额 | C26: 万元 | D26: =SUM(E26:H26) -> 1.0518478 | E26: =E23-E24-E25 -> -104.31851 | F26: =F23-F24-F25 -> 91.358819 | G26: =G23-G24-G25 -> -54.033844 | H26: =H23-H24-H25 -> 68.045383 | I26: =I25*10% -> 6.7494514
E28: =1178+73 -> 1251
E29: =E28*0.85 -> 1063.35
E30: =E28-E29 -> 187.65
E31: =E24-4.6 -> 231.24329
E32: =E31*0.16 -> 36.998926
O37: 20000
D38: Q2预测 | E38: 合同负债 | F38: 66所学校 | G38: 政企培训 | H38: 实验室改造 | J38: 预测 | K38: 预算 | O38: 3 | P38: 30000
D39: 收入 | E39: =(40+4+9.9+2.48)/1.01 -> 55.821782 | F39: =(58+8)*12/1.06 -> 747.16981 | G39: =200/1.06 -> 188.67925 | H39: =1058.3-991.67 -> 66.63 | J39: =SUM(E39:I39) -> 1058.3008 | K39: 1062.4223 | O39: =O37*O38 -> 60000 | P39: =O37*P38 -> 600000000
D40: 现金流入 | E40: =4+2 -> 6 | F40: =F39*1.06*0.5 -> 396 | G40: =G39*1.06 -> 200 | H40: =(400+300)*0.1 -> 70 | J40: =SUM(E40:I40) -> 672 | K40: 689.95337 | O40: =O39/20 -> 3000 | P40: =P39/20 -> 30000000
D41: 现金流出 | E41: =SUM('附件3 经营性资金计划 2026415'!I14:K14)+47.26 -> 656.4352 | F41: =150/3+'附件3 经营性资金计划 2026415'!J18+'附件3 经营性资金计划 2026415'!K18 -> 174.5 | G41: =SUM('附件3 经营性资金计划 2026415'!J19:K19) -> 16.867141 | H41: =SUM('附件3 经营性资金计划 2026415'!I20:K20)*0.85 -> 61.659 | J41: =SUM(E41:I41) -> 909.46134 | K41: 764.83694
D42: 现金流净额 | E42: 采购成本 | F42: 人工成本 | G42: 税费 | H42: 运营费用 | J42: =J40-J41 -> -237.46134 | K42: =K40-K41 -> -74.883577

Sheet 简表
A1: 2026年新版预算数据
A2: 项目 | B2: 新版 | C2: 原版 | D2: 差异
A3: 收入 | B3: ='附件2 经营性净现金流利润编制明细2026415'!E5 -> 2884.035 | C3: 2931.67 | D3: =B3-C3 -> -47.635031 | E3: 调减收入108万
A4: 成本 | B4: ='附件2 经营性净现金流利润编制明细2026415'!E15 -> 1686.0397 | C4: 1666.34 | D4: =B4-C4 -> 19.699748 | E4: 调减成本40万
A5: 销管研费用 | B5: ='附件2 经营性净现金流利润编制明细2026415'!E24+'附件2 经营性净现金流利润编制明细2026415'!E27+'附件2 经营性净现金流利润编制明细2026415'!E30 -> 1163.7141 | C5: 1178 | D5: =B5-C5 -> -14.285941 | E5: 增加opc运营人工成本（4人）73万、调减8投流等费用87万
A6: 利润总额 | B6: ='附件2 经营性净现金流利润编制明细2026415'!E38 -> 1.0398117 | C6: 54.33 | D6: =B6-C6 -> -53.290188 | E6: ↓
A7: 经营性现金流入 | B7: ='附件3 经营性资金计划 2026415'!E5 -> 3003.0213 | C7: 2883.44 | D7: =B7-C7 -> 119.5813 | E7: 调减回款4万
A8: 经营性现金流出 | B8: ='附件3 经营性资金计划 2026415'!E13 -> 2988.8499 | C8: 2865 | D8: =B8-C8 -> 123.84991 | E8: 增加采购支出17万，增加人工成本支出63万，减少投流费用87万
A9: 现金净流量 | B9: ='附件3 经营性资金计划 2026415'!E22 -> 14.171394 | C9: 18.44 | D9: =B9-C9 -> -4.2686064 | E9: ↓
